Workbook

Sheet Data
A1: date | C1: NESN | D1: SREN | E1: NOVN | G1: SMI | I1: R_NESN | J1: R_SREN | K1: R_NOVN
A2: 43542 | C2: 94.16 | D2: 99.82 | E2: 78.15365 | G2: 0.00146
A3: 43543 | C3: 94.6 | D3: 99.62 | E3: 78.0196 | G3: 0.0030521266 | I3: =(C3/C2)-1 -> 0.0046728972 | J3: =(D3/D2)-1 -> -0.0020036065 | K3: =(E3/E2)-1 -> -0.001715211
A4: 43544 | C4: 94.66 | D4: 97.86 | E4: 77.81851 | G4: -0.0065717422 | I4: =(C4/C3)-1 -> 0.00063424947 | J4: =(D4/D3)-1 -> -0.017667135 | K4: =(E4/E3)-1 -> -0.0025774293
A5: 43545 | C5: 95.44 | D5: 97.62 | E5: 78.053116 | G5: -0.00097862077 | I5: =(C5/C4)-1 -> 0.0082400169 | J5: =(D5/D4)-1 -> -0.0024524831 | K5: =(E5/E4)-1 -> 0.003014784
A6: 43546 | C6: 93.86 | D6: 96.44 | E6: 77.952576 | G6: -0.014240674 | I6: =(C6/C5)-1 -> -0.016554904 | J6: =(D6/D5)-1 -> -0.012087687 | K6: =(E6/E5)-1 -> -0.0012880972
A7: 43549 | C7: 94.06 | D7: 96.64 | E7: 77.51689 | G7: -0.0014937968 | I7: =(C7/C6)-1 -> 0.0021308332 | J7: =(D7/D6)-1 -> 0.0020738283 | K7: =(E7/E6)-1 -> -0.0055891161
A8: 43550 | C8: 95.2 | D8: 96.52 | E8: 79.02501 | G8: 0.0090053853 | I8: =(C8/C7)-1 -> 0.012119923 | J8: =(D8/D7)-1 -> -0.0012417219 | K8: =(E8/E7)-1 -> 0.019455373
A9: 43551 | C9: 95.3 | D9: 96.82 | E9: 79.10879 | G9: 0.00013782473 | I9: =(C9/C8)-1 -> 0.0010504202 | J9: =(D9/D8)-1 -> 0.0031081641 | K9: =(E9/E8)-1 -> 0.0010601707
A10: 43552 | C10: 95.2 | D10: 96.86 | E10: 79.89636 | G10: 0.0016332357 | I10: =(C10/C9)-1 -> -0.0010493179 | J10: =(D10/D9)-1 -> 0.00041313778 | K10: =(E10/E9)-1 -> 0.0099555309
A11: 43553 | C11: 94.9 | D11: 97.28 | E11: 80.248245 | G11: 0.0076454722 | I11: =(C11/C10)-1 -> -0.0031512605 | J11: =(D11/D10)-1 -> 0.0043361553 | K11: =(E11/E10)-1 -> 0.0044042682
A12: 43556 | C12: 94.63 | D12: 98.22 | E12: 80.46609 | G12: 0.0063580599 | I12: =(C12/C11)-1 -> -0.0028451001 | J12: =(D12/D11)-1 -> 0.0096628289 | K12: =(E12/E11)-1 -> 0.0027146388
A13: 43557 | C13: 94.81 | D13: 99.02 | E13: 79.47744 | G13: -0.00016077409 | I13: =(C13/C12)-1 -> 0.0019021452 | J13: =(D13/D12)-1 -> 0.0081449807 | K13: =(E13/E12)-1 -> -0.012286542
A14: 43558 | C14: 95.39 | D14: 99.72 | E14: 79.17582 | G14: 0.0035147712 | I14: =(C14/C13)-1 -> 0.0061174982 | J14: =(D14/D13)-1 -> 0.0070692789 | K14: =(E14/E13)-1 -> -0.0037950392
... A1470: 45729 | C1470: 89.24 | D1470: 146.65 | E1470: 96.93 | G1470: -0.0025054537 | I1470: =(C1470/C1469)-1 -> 0.0022461815 | J1470: =(D1470/D1469)-1 -> -0.0033978933 | K1470: =(E1470/E1469)-1 -> 0.0064375454

Sheet Parametric VaR Analysis
D3: NESN | E3: SREN | F3: NOVN | H3: VaR(99%,1) between 12.11.21 - 14.03.24
C4: Volatility | D4: =STDEV(D9:D132) -> 0.010902136 | E4: =STDEV(E9:E132) -> 0.014693466 | F4: =STDEV(F9:F132) -> 0.010082312 | H4: date | I4: Value_NESN | J4: VaR_NESN | K4: Value_SREN | L4: VaR_SREN | M4: Value_NOVN | N4: VaR_NOVN | O4: VaR_π
C5: Position | D5: -30000 | E5: 70000 | F5: 80000 | H5: 44886 | I5: =$D$5*Data!C908 -> -3364200 | J5: =I5*$D$4*_xlfn.NORM.S.INV(0.01) -> 85323.382 | K5: =$E$5*Data!D908 -> 5608400 | L5: =K5*$E$4*_xlfn.NORM.S.INV(0.99) -> 191706.96 | M5: =$F$5*Data!E908 -> 6288031.2 | N5: =M5*$F$4*_xlfn.NORM.S.INV(0.99) -> 147485.55 | O5: =N5+L5+J5 -> 424515.9
H6: 44887 | I6: =$D$5*Data!C909 -> -3368400 | J6: =I6*$D$4*_xlfn.NORM.S.INV(0.01) -> 85429.903 | K6: =$E$5*Data!D909 -> 5612600 | L6: =K6*$E$4*_xlfn.NORM.S.INV(0.99) -> 191850.53 | M6: =$F$5*Data!E909 -> 6332766.7 | N6: =M6*$F$4*_xlfn.NORM.S.INV(0.99) -> 148534.83 | O6: =N6+L6+J6 -> 425815.26
H7: 44888 | I7: =$D$5*Data!C910 -> -3387600 | J7: =I7*$D$4*_xlfn.NORM.S.INV(0.01) -> 85916.856 | K7: =$E$5*Data!D910 -> 5713400 | L7: =K7*$E$4*_xlfn.NORM.S.INV(0.99) -> 195296.08 | M7: =$F$5*Data!E910 -> 6221306.8 | N7: =M7*$F$4*_xlfn.NORM.S.INV(0.99) -> 145920.54 | O7: =N7+L7+J7 -> 427133.48
B8: date | D8: NESN | E8: SREN | F8: NOVN | H8: 44890 | I8: =$D$5*Data!C911 -> -3390000 | J8: =I8*$D$4*_xlfn.NORM.S.INV(0.01) -> 85977.726 | K8: =$E$5*Data!D911 -> 5780600 | L8: =K8*$E$4*_xlfn.NORM.S.INV(0.99) -> 197593.12 | M8: =$F$5*Data!E911 -> 6295613.6 | N8: =M8*$F$4*_xlfn.NORM.S.INV(0.99) -> 147663.4 | O8: =N8+L8+J8 -> 431234.25
B9: 44887 | D9: -0.050259675 | E9: -0.03515625 | F9: -0.015057381 | H9: 44893 | I9: =$D$5*Data!C912 -> -3405000 | J9: =I9*$D$4*_xlfn.NORM.S.INV(0.01) -> 86358.158 | K9: =$E$5*Data!D912 -> 5864600 | L9: =K9*$E$4*_xlfn.NORM.S.INV(0.99) -> 200464.42 | M9: =$F$5*Data!E912 -> 6314568.8 | N9: =M9*$F$4*_xlfn.NORM.S.INV(0.99) -> 148107.99 | O9: =N9+L9+J9 -> 434930.57
B10: 44888 | D10: -0.0015875816 | E10: -0.0010121457 | F10: 0.01178655 | H10: 44894 | I10: =$D$5*Data!C913 -> -3337800 | J10: =I10*$D$4*_xlfn.NORM.S.INV(0.01) -> 84653.821 | K10: =$E$5*Data!D913 -> 5916400 | L10: =K10*$E$4*_xlfn.NORM.S.INV(0.99) -> 202235.05 | M10: =$F$5*Data!E913 -> 6316085.6 | N10: =M10*$F$4*_xlfn.NORM.S.INV(0.99) -> 148143.57 | O10: =N10+L10+J10 -> 435032.44
B11: 44890 | D11: 0.012897527 | E11: 0.007852077 | F11: 0.011303392 | H11: 44895 | I11: =$D$5*Data!C914 -> -3370200 | J11: =I11*$D$4*_xlfn.NORM.S.INV(0.01) -> 85475.555 | K11: =$E$5*Data!D914 -> 5895400 | L11: =K11*$E$4*_xlfn.NORM.S.INV(0.99) -> 201517.23 | M11: =$F$5*Data!E914 -> 6342624 | N11: =M11*$F$4*_xlfn.NORM.S.INV(0.99) -> 148766.03 | O11: =N11+L11+J11 -> 435758.81
B12: 44893 | D12: 0.00069771498 | E12: -0.011058055 | F12: 0 | H12: 44896 | I12: =$D$5*Data!C915 -> -3411600 | J12: =I12*$D$4*_xlfn.NORM.S.INV(0.01) -> 86525.548 | K12: =$E$5*Data!D915 -> 5948600 | L12: =K12*$E$4*_xlfn.NORM.S.INV(0.99) -> 203335.72 | M12: =$F$5*Data!E915 -> 6376744.4 | N12: =M12*$F$4*_xlfn.NORM.S.INV(0.99) -> 149566.32 | O12: =N12+L12+J12 -> 439427.59
B13: 44894 | D13: -0.0043576782 | E13: 0.0030495553 | F13: 0.0015967048 | H13: 44897 | I13: =$D$5*Data!C916 -> -3390000 | J13: =I13*$D$4*_xlfn.NORM.S.INV(0.01) -> 85977.726 | K13: =$E$5*Data!D916 -> 5926200 | L13: =K13*$E$4*_xlfn.NORM.S.INV(0.99) -> 202570.04 | M13: =$F$5*Data!E916 -> 6379777.2 | N13: =M13*$F$4*_xlfn.NORM.S.INV(0.99) -> 149637.45 | O13: =N13+L13+J13 -> 438185.22
B14: 44895 | D14: 0.020483193 | E14: 0.017988346 | F14: -0.0079707969 | H14: 44900 | I14: =$D$5*Data!C917 -> -3339000 | J14: =I14*$D$4*_xlfn.NORM.S.INV(0.01) -> 84684.255 | K14: =$E$5*Data!D917 -> 5982200 | L14: =K14*$E$4*_xlfn.NORM.S.INV(0.99) -> 204484.24 | M14: =$F$5*Data!E917 -> 6505644.8 | N14: =M14*$F$4*_xlfn.NORM.S.INV(0.99) -> 152589.67 | O14: =N14+L14+J14 -> 441758.17
B15: 44896 | D15: 0.0036026763 | E15: -0.017919363 | F15: -0.0029844387 | H15: 44901 | I15: =$D$5*Data!C918 -> -3347400 | J15: =I15*$D$4*_xlfn.NORM.S.INV(0.01) -> 84897.298 | K15: =$E$5*Data!D918 -> 5950000 | L15: =K15*$E$4*_xlfn.NORM.S.INV(0.99) -> 203383.57 | M15: =$F$5*Data!E918 -> 6466216 | N15: =M15*$F$4*_xlfn.NORM.S.INV(0.99) -> 151664.87 | O15: =N15+L15+J15 -> 439945.74
B16: 44897 | D16: -0.016410256 | E16: -0.010136847 | F16: -0.0078285862 | H16: 44902 | I16: =$D$5*Data!C919 -> -3277800 | J16: =I16*$D$4*_xlfn.NORM.S.INV(0.01) -> 83132.091 | K16: =$E$5*Data!D919 -> 5944400 | L16: =K16*$E$4*_xlfn.NORM.S.INV(0.99) -> 203192.15 | M16: =$F$5*Data!E919 -> 6504128 | N16: =M16*$F$4*_xlfn.NORM.S.INV(0.99) -> 152554.1 | O16: =N16+L16+J16 -> 438878.34
B17: 44900 | D17: -0.0029544665 | E17: 0.0040962622 | F17: -0.0067301072 | H17: 44903 | I17: =$D$5*Data!C920 -> -3282600 | J17: =I17*$D$4*_xlfn.NORM.S.INV(0.01) -> 83253.83 | K17: =$E$5*Data!D920 -> 6050800 | L17: =K17*$E$4*_xlfn.NORM.S.INV(0.99) -> 206829.13 | M17: =$F$5*Data!E920 -> 6467732.8 | N17: =M17*$F$4*_xlfn.NORM.S.INV(0.99) -> 151700.45 | O17: =N17+L17+J17 -> 441783.41
B18: 44901 | D18: 0.001394457 | E18: 0.0025497195 | F18: 0.0026868891 | H18: 44904 | I18: =$D$5*Data!C921 -> -3277200 | J18: =I18*$D$4*_xlfn.NORM.S.INV(0.01) -> 83116.874 | K18: =$E$5*Data!D921 -> 6092800 | L18: =K18*$E$4*_xlfn.NORM.S.INV(0.99) -> 208264.78 | M18: =$F$5*Data!E921 -> 6481381.2 | N18: =M18*$F$4*_xlfn.NORM.S.INV(0.99) -> 152020.57 | O18: =N18+L18+J18 -> 443402.22
B19: 44902 | D19: -0.0092254134 | E19: 0.018565615 | F19: 0.0011649807 | H19: 44907 | I19: =$D$5*Data!C922 -> -3285000 | J19: =I19*$D$4*_xlfn.NORM.S.INV(0.01) -> 83314.699 | K19: =$E$5*Data!D922 -> 6025600 | L19: =K19*$E$4*_xlfn.NORM.S.INV(0.99) -> 205967.74 | M19: =$F$5*Data!E922 -> 6439677.6 | N19: =M19*$F$4*_xlfn.NORM.S.INV(0.99) -> 151042.42 | O19: =N19+L19+J19 -> 440324.85
B20: 44903 | D20: -0.012825018 | E20: -0.016229713 | F20: -0.001745499 | H20: 44908 | I20: =$D$5*Data!C923 -> -3286800 | J20: =I20*$D$4*_xlfn.NORM.S.INV(0.01) -> 83360.351 | K20: =$E$5*Data!D923 -> 6052200 | L20: =K20*$E$4*_xlfn.NORM.S.INV(0.99) -> 206876.98 | M20: =$F$5*Data!E923 -> 6429821.2 | N20: =M20*$F$4*_xlfn.NORM.S.INV(0.99) -> 150811.23 | O20: =N20+L20+J20 -> 441048.57
... B34: 44924 | D34: 0.015907448 | E34: -0.01062417 | F34: 0.00061622411 | H34: 44930 | I34: =$D$5*Data!C937 -> -3324000 | J34: =I34*$D$4*_xlfn.NORM.S.INV(0.01) -> 84303.823 | K34: =$E$5*Data!D937 -> 6557600 | L34: =K34*$E$4*_xlfn.NORM.S.INV(0.99) -> 224152.62 | M34: =$F$5*Data!E937 -> 6501852.8 | N34: =M34*$F$4*_xlfn.NORM.S.INV(0.99) -> 152500.73 | O34: =N34+L34+J34 -> 460957.18
B35: 44925 | D35: -0.0085409253 | E35: -0.0069798658 | F35: -0.0041877173 | H35: 44931 | I35: =$D$5*Data!C938 -> -3314400 | J35: =I35*$D$4*_xlfn.NORM.S.INV(0.01) -> 84060.346 | K35: =$E$5*Data!D938 -> 6540800 | L35: =K35*$E$4*_xlfn.NORM.S.INV(0.99) -> 223578.36 | M35: =$F$5*Data!E938 -> 6437403.6 | N35: =M35*$F$4*_xlfn.NORM.S.INV(0.99) -> 150989.08 | O35: =N35+L35+J35 -> 458627.79 | Q35: Comments
B36: 44929 | D36: 0.011844939 | E36: -0.00054068667 | F36: -0.0064316398 | H36: 44932 | I36: =$D$5*Data!C939 -> -3333000 | J36: =I36*$D$4*_xlfn.NORM.S.INV(0.01) -> 84532.082 | K36: =$E$5*Data!D939 -> 6643000 | L36: =K36*$E$4*_xlfn.NORM.S.INV(0.99) -> 227071.78 | M36: =$F$5*Data!E939 -> 6503369.1 | N36: =M36*$F$4*_xlfn.NORM.S.INV(0.99) -> 152536.3 | O36: =N36+L36+J36 -> 464140.16 | Q36: There are some significant limitations of this approach : - Igonring correlations between assets, - Being too optimistic about representiveness of the data.
B37: 44930 | D37: 0.00070947144 | E37: -0.031647282 | F37: 0.0072202251 | H37: 44935 | I37: =$D$5*Data!C940 -> -3348600 | J37: =I37*$D$4*_xlfn.NORM.S.INV(0.01) -> 84927.732 | K37: =$E$5*Data!D940 -> 6582800 | L37: =K37*$E$4*_xlfn.NORM.S.INV(0.99) -> 225014.01 | M37: =$F$5*Data!E940 -> 6468490.4 | N37: =M37*$F$4*_xlfn.NORM.S.INV(0.99) -> 151718.22 | O37: =N37+L37+J37 -> 461659.97
B38: 44931 | D38: 0.018787664 | E38: -0.0025139665 | F38: 0.0038314761 | H38: 44936 | I38: =$D$5*Data!C941 -> -3341400 | J38: =I38*$D$4*_xlfn.NORM.S.INV(0.01) -> 84745.125 | K38: =$E$5*Data!D941 -> 6500200 | L38: =K38*$E$4*_xlfn.NORM.S.INV(0.99) -> 222190.57 | M38: =$F$5*Data!E941 -> 6332766.7 | N38: =M38*$F$4*_xlfn.NORM.S.INV(0.99) -> 148534.83 | O38: =N38+L38+J38 -> 455470.52
B39: 44932 | D39: -0.0050452331 | E39: 0.03108373 | F39: 0.01095788 | H39: 44937 | I39: =$D$5*Data!C942 -> -3389400 | J39: =I39*$D$4*_xlfn.NORM.S.INV(0.01) -> 85962.508 | K39: =$E$5*Data!D942 -> 6405000 | L39: =K39*$E$4*_xlfn.NORM.S.INV(0.99) -> 218936.43 | M39: =$F$5*Data!E942 -> 6361580 | N39: =M39*$F$4*_xlfn.NORM.S.INV(0.99) -> 149210.64 | O39: =N39+L39+J39 -> 454109.58
B40: 44935 | D40: 0.0022731247 | E40: 0.0048886475 | F40: 0.0079162251 | H40: 44938 | I40: =$D$5*Data!C943 -> -3407400 | J40: =I40*$D$4*_xlfn.NORM.S.INV(0.01) -> 86419.027 | K40: =$E$5*Data!D943 -> 6526800 | L40: =K40*$E$4*_xlfn.NORM.S.INV(0.99) -> 223099.82 | M40: =$F$5*Data!E943 -> 6378261.1 | N40: =M40*$F$4*_xlfn.NORM.S.INV(0.99) -> 149601.89 | O40: =N40+L40+J40 -> 459120.74
B41: 44936 | D41: 0.0047103978 | E41: -0.017297297 | F41: 0.002899823 | H41: 44939 | I41: =$D$5*Data!C944 -> -3418800 | J41: =I41*$D$4*_xlfn.NORM.S.INV(0.01) -> 86708.156 | K41: =$E$5*Data!D944 -> 6484800 | L41: =K41*$E$4*_xlfn.NORM.S.INV(0.99) -> 221664.17 | M41: =$F$5*Data!E944 -> 6407074 | N41: =M41*$F$4*_xlfn.NORM.S.INV(0.99) -> 150277.7 | O41: =N41+L41+J41 -> 458650.02
B42: 44937 | D42: 0.0039937489 | E42: 0.016226623 | F42: -0.00096381278 | H42: 44943 | I42: =$D$5*Data!C945 -> -3438000 | J42: =I42*$D$4*_xlfn.NORM.S.INV(0.01) -> 87195.109 | K42: =$E$5*Data!D945 -> 6445600 | L42: =K42*$E$4*_xlfn.NORM.S.INV(0.99) -> 220324.23 | M42: =$F$5*Data!E945 -> 6491237.6 | N42: =M42*$F$4*_xlfn.NORM.S.INV(0.99) -> 152251.75 | O42: =N42+L42+J42 -> 459771.09
B43: 44938 | D43: -0.015738499 | E43: -0.014614344 | F43: -0.017607253 | H43: 44944 | I43: =$D$5*Data!C946 -> -3373200 | J43: =I43*$D$4*_xlfn.NORM.S.INV(0.01) -> 85551.641 | K43: =$E$5*Data!D946 -> 6538000 | L43: =K43*$E$4*_xlfn.NORM.S.INV(0.99) -> 223482.65 | M43: =$F$5*Data!E946 -> 6425271.6 | N43: =M43*$F$4*_xlfn.NORM.S.INV(0.99) -> 150704.52 | O43: =N43+L43+J43 -> 459738.82
B44: 44939 | D44: -0.0066772096 | E44: -0.020324087 | F44: -0.0054014434 | H44: 44945 | I44: =$D$5*Data!C947 -> -3369600 | J44: =I44*$D$4*_xlfn.NORM.S.INV(0.01) -> 85460.338 | K44: =$E$5*Data!D947 -> 6508600 | L44: =K44*$E$4*_xlfn.NORM.S.INV(0.99) -> 222477.7 | M44: =$F$5*Data!E947 -> 6407832 | N44: =M44*$F$4*_xlfn.NORM.S.INV(0.99) -> 150295.48 | O44: =N44+L44+J44 -> 458233.52
B45: 44943 | D45: 0.0191049 | E45: 0.0081300813 | F45: 0.019748246 | H45: 44946 | I45: =$D$5*Data!C948 -> -3361200 | J45: =I45*$D$4*_xlfn.NORM.S.INV(0.01) -> 85247.295 | K45: =$E$5*Data!D948 -> 6608000 | L45: =K45*$E$4*_xlfn.NORM.S.INV(0.99) -> 225875.4 | M45: =$F$5*Data!E948 -> 6405557.6 | N45: =M45*$F$4*_xlfn.NORM.S.INV(0.99) -> 150242.13 | O45: =N45+L45+J45 -> 461364.83
B46: 44944 | D46: -0.0024301337 | E46: 0.0072302558 | F46: -0.0061728657 | H46: 44949 | I46: =$D$5*Data!C949 -> -3395400 | J46: =I46*$D$4*_xlfn.NORM.S.INV(0.01) -> 86114.681 | K46: =$E$5*Data!D949 -> 6592600 | L46: =K46*$E$4*_xlfn.NORM.S.INV(0.99) -> 225349 | M46: =$F$5*Data!E949 -> 6477589.6 | N46: =M46*$F$4*_xlfn.NORM.S.INV(0.99) -> 151931.64 | O46: =N46+L46+J46 -> 463395.32
B47: 44945 | D47: 0.0029580651 | E47: 0.0071783545 | F47: 0.014614484 | H47: 44950 | I47: =$D$5*Data!C950 -> -3376800 | J47: =I47*$D$4*_xlfn.NORM.S.INV(0.01) -> 85642.945 | K47: =$E$5*Data!D950 -> 6704600 | L47: =K47*$E$4*_xlfn.NORM.S.INV(0.99) -> 229177.39 | M47: =$F$5*Data!E950 -> 6449535.2 | N47: =M47*$F$4*_xlfn.NORM.S.INV(0.99) -> 151273.63 | O47: =N47+L47+J47 -> 466093.97
B48: 44946 | D48: -0.017522554 | E48: -0.010142544 | F48: -0.012363516 | H48: 44951 | I48: =$D$5*Data!C951 -> -3381000 | J48: =I48*$D$4*_xlfn.NORM.S.INV(0.01) -> 85749.466 | K48: =$E$5*Data!D951 -> 6694800 | L48: =K48*$E$4*_xlfn.NORM.S.INV(0.99) -> 228842.41 | M48: =$F$5*Data!E951 -> 6467732.8 | N48: =M48*$F$4*_xlfn.NORM.S.INV(0.99) -> 151700.45 | O48: =N48+L48+J48 -> 466292.33
... B132: 45071 | D132: 0.013092384 | E132: 0.005325894 | F132: 0.00050605045 | H132: 45077 | I132: =$D$5*Data!C1035 -> -3237000 | J132: =I132*$D$4*_xlfn.NORM.S.INV(0.01) -> 82097.315 | K132: =$E$5*Data!D1035 -> 6385400 | L132: =K132*$E$4*_xlfn.NORM.S.INV(0.99) -> 218266.46 | M132: =$F$5*Data!E1035 -> 6608764 | N132: =M132*$F$4*_xlfn.NORM.S.INV(0.99) -> 155008.33 | O132: =N132+L132+J132 -> 455372.11
H133: 45078 | I133: =$D$5*Data!C1036 -> -3263400 | J133: =I133*$D$4*_xlfn.NORM.S.INV(0.01) -> 82766.876 | K133: =$E$5*Data!D1036 -> 6494600 | L133: =K133*$E$4*_xlfn.NORM.S.INV(0.99) -> 221999.15 | M133: =$F$5*Data!E1036 -> 6677004.8 | N133: =M133*$F$4*_xlfn.NORM.S.INV(0.99) -> 156608.92 | O133: =N133+L133+J133 -> 461374.94
H134: 45079 | I134: =$D$5*Data!C1037 -> -3288000 | J134: =I134*$D$4*_xlfn.NORM.S.INV(0.01) -> 83390.785 | K134: =$E$5*Data!D1037 -> 6524000 | L134: =K134*$E$4*_xlfn.NORM.S.INV(0.99) -> 223004.11 | M134: =$F$5*Data!E1037 -> 6776333.6 | N134: =M134*$F$4*_xlfn.NORM.S.INV(0.99) -> 158938.67 | O134: =N134+L134+J134 -> 465333.56
H135: 45082 | I135: =$D$5*Data!C1038 -> -3263400 | J135: =I135*$D$4*_xlfn.NORM.S.INV(0.01) -> 82766.876 | K135: =$E$5*Data!D1038 -> 6459600 | L135: =K135*$E$4*_xlfn.NORM.S.INV(0.99) -> 220802.78 | M135: =$F$5*Data!E1038 -> 6852915.2 | N135: =M135*$F$4*_xlfn.NORM.S.INV(0.99) -> 160734.89 | O135: =N135+L135+J135 -> 464304.54
H136: 45083 | I136: =$D$5*Data!C1039 -> -3274800 | J136: =I136*$D$4*_xlfn.NORM.S.INV(0.01) -> 83056.005 | K136: =$E$5*Data!D1039 -> 6470800 | L136: =K136*$E$4*_xlfn.NORM.S.INV(0.99) -> 221185.62 | M136: =$F$5*Data!E1039 -> 6863530.4 | N136: =M136*$F$4*_xlfn.NORM.S.INV(0.99) -> 160983.87 | O136: =N136+L136+J136 -> 465225.49
H137: 45084 | I137: =$D$5*Data!C1040 -> -3234600 | J137: =I137*$D$4*_xlfn.NORM.S.INV(0.01) -> 82036.446 | K137: =$E$5*Data!D1040 -> 6388200 | L137: =K137*$E$4*_xlfn.NORM.S.INV(0.99) -> 218362.17 | M137: =$F$5*Data!E1040 -> 6786190.8 | N137: =M137*$F$4*_xlfn.NORM.S.INV(0.99) -> 159169.87 | O137: =N137+L137+J137 -> 459568.49
H138: 45085 | I138: =$D$5*Data!C1041 -> -3210000 | J138: =I138*$D$4*_xlfn.NORM.S.INV(0.01) -> 81412.537 | K138: =$E$5*Data!D1041 -> 6279000 | L138: =K138*$E$4*_xlfn.NORM.S.INV(0.99) -> 214629.49 | M138: =$F$5*Data!E1041 -> 6852156.8 | N138: =M138*$F$4*_xlfn.NORM.S.INV(0.99) -> 160717.1 | O138: =N138+L138+J138 -> 456759.13
...

Sheet Asset-Normal Portfolio VaR
C3: NESN | D3: SREN | E3: NOVN
B4: Position | C4: -30000 | D4: 70000 | E4: 80000
B6: Var - Cov Matrix | C6: NESN | D6: SREN | E6: NOVN
B7: NESN | C7: =_xlfn.VAR.S(C14:C263) -> 0.00012892024 | D7: =_xlfn.COVARIANCE.S(D14:D263,C14:C263) -> 4.3332926e-05 | E7: =_xlfn.COVARIANCE.S(E14:E263,C14:C263) -> 6.3046607e-05
B8: SREN | C8: =_xlfn.COVARIANCE.S(C14:C263,D14:D263) -> 4.3332926e-05 | D8: =_xlfn.VAR.S(D14:D263) -> 0.00025221438 | E8: =_xlfn.COVARIANCE.S(E14:E263,D14:D263) -> 5.0775455e-05
B9: NOVN | C9: =_xlfn.COVARIANCE.S(C14:C263,E14:E263) -> 6.3046607e-05 | D9: =_xlfn.COVARIANCE.S(D14:D263,E14:E263) -> 5.0775455e-05 | E9: =_xlfn.VAR.S(E14:E263) -> 0.0001250704
B13: Date | C13: NESN | D13: SREN | E13: NOVN | G13: Date | H13: VaLUE_NESN | I13: Value_SREN | J13: Value_NOVN | K13: VaR_π_AN
B14: 44516 | C14: 0.0038992689 | D14: 0.00022522523 | E14: 0.0039370411 | G14: 44886 | H14: -3364200 | I14: 5608400 | J14: 6288031.2 | K14: {=_xlfn.NORM.S.INV(0.99)*SQRT(MMULT(MMULT(H14:J14,$C$7:$E$9),TRANSPOSE(H14:J14)))} -> 271457.68
B15: 44517 | C15: -0.00097103091 | D15: -0.00067552353 | E15: -0.0036601063 | G15: 44887 | H15: -3368400 | I15: 5612600 | J15: 6332766.7 | K15: {=_xlfn.NORM.S.INV(0.99)*SQRT(MMULT(MMULT(H15:J15,$C$7:$E$9),TRANSPOSE(H15:J15)))} -> 272340.7
B16: 44518 | C16: -0.0025919326 | D16: -0.0045065345 | E16: -0.0061664676 | G16: 44888 | H16: -3387600 | I16: 5713400 | J16: 6221306.8 | K16: {=_xlfn.NORM.S.INV(0.99)*SQRT(MMULT(MMULT(H16:J16,$C$7:$E$9),TRANSPOSE(H16:J16)))} -> 273561.66
B17: 44519 | C17: -0.0030859185 | D17: -0.0097329108 | E17: 0.0038285268 | G17: 44890 | H17: -3390000 | I17: 5780600 | J17: 6295613.6 | K17: {=_xlfn.NORM.S.INV(0.99)*SQRT(MMULT(MMULT(H17:J17,$C$7:$E$9),TRANSPOSE(H17:J17)))} -> 276950.6
B18: 44522 | C18: -0.0011404366 | D18: 0.0061714286 | E18: 0.0019725237 | G18: 44893 | H18: -3405000 | I18: 5864600 | J18: 6314568.8 | K18: {=_xlfn.NORM.S.INV(0.99)*SQRT(MMULT(MMULT(H18:J18,$C$7:$E$9),TRANSPOSE(H18:J18)))} -> 279889.55
B19: 44523 | C19: -0.0047300603 | D19: 0.0047705588 | E19: 0.010631296 | G19: 44894 | H19: -3337800 | I19: 5916400 | J19: 6316085.6 | K19: {=_xlfn.NORM.S.INV(0.99)*SQRT(MMULT(MMULT(H19:J19,$C$7:$E$9),TRANSPOSE(H19:J19)))} -> 281855.5
B20: 44524 | C20: -0.0042608981 | D20: 0.0067827267 | E20: -0.0058440685 | G20: 44895 | H20: -3370200 | I20: 5895400 | J20: 6342624 | K20: {=_xlfn.NORM.S.INV(0.99)*SQRT(MMULT(MMULT(H20:J20,$C$7:$E$9),TRANSPOSE(H20:J20)))} -> 281493.64
B21: 44526 | C21: -0.0083936801 | D21: -0.031439479 | E21: -0.023906007 | G21: 44896 | H21: -3411600 | I21: 5948600 | J21: 6376744.4 | K21: {=_xlfn.NORM.S.INV(0.99)*SQRT(MMULT(MMULT(H21:J21,$C$7:$E$9),TRANSPOSE(H21:J21)))} -> 283596.8
B22: 44529 | C22: -0.0033195021 | D22: 0.0046371435 | E22: -0.0064239949 | G22: 44897 | H22: -3390000 | I22: 5926200 | J22: 6379777.2 | K22: {=_xlfn.NORM.S.INV(0.99)*SQRT(MMULT(MMULT(H22:J22,$C$7:$E$9),TRANSPOSE(H22:J22)))} -> 283022.95
B23: 44530 | C23: -0.017485429 | D23: -0.0025386568 | E23: -0.010775882 | G23: 44900 | H23: -3339000 | I23: 5982200 | J23: 6505644.8 | K23: {=_xlfn.NORM.S.INV(0.99)*SQRT(MMULT(MMULT(H23:J23,$C$7:$E$9),TRANSPOSE(H23:J23)))} -> 287175.98
B24: 44531 | C24: 0.0013559322 | D24: 0.012494216 | E24: 0.010893267 | G24: 44901 | H24: -3347400 | I24: 5950000 | J24: 6466216 | K24: {=_xlfn.NORM.S.INV(0.99)*SQRT(MMULT(MMULT(H24:J24,$C$7:$E$9),TRANSPOSE(H24:J24)))} -> 285437.03
B25: 44532 | C25: -0.0030467163 | D25: 0.00068555759 | E25: -0.0059266749 | G25: 44902 | H25: -3277800 | I25: 5944400 | J25: 6504128 | K25: {=_xlfn.NORM.S.INV(0.99)*SQRT(MMULT(MMULT(H25:J25,$C$7:$E$9),TRANSPOSE(H25:J25)))} -> 286223
... B44: 44560 | C44: -0.0070126227 | D44: -0.0033127208 | E44: -0.00062243773 | G44: 44931 | H44: -3314400 | I44: 6540800 | J44: 6437403.6 | K44: {=_xlfn.NORM.S.INV(0.99)*SQRT(MMULT(MMULT(H44:J44,$C$7:$E$9),TRANSPOSE(H44:J44)))} -> 304175.07
B45: 44564 | C45: 0.013967357 | D45: 0.014181254 | E45: 0.0006228254 | G45: 44932 | H45: -3333000 | I45: 6643000 | J45: 6503369.1 | K45: {=_xlfn.NORM.S.INV(0.99)*SQRT(MMULT(MMULT(H45:J45,$C$7:$E$9),TRANSPOSE(H45:J45)))} -> 308511.75 | M45: Comments
B46: 44565 | C46: 0.0021668472 | D46: 0.011361154 | E46: 0.0017427994 | G46: 44935 | H46: -3348600 | I46: 6582800 | J46: 6468490.4 | K46: {=_xlfn.NORM.S.INV(0.99)*SQRT(MMULT(MMULT(H46:J46,$C$7:$E$9),TRANSPOSE(H46:J46)))} -> 305899.13 | M46: This approach indicates lower VaR than first one because the correlations are taken into account.
B47: 44566 | C47: -0.027027027 | D47: 0.0082091164 | E47: 0.0078290185 | G47: 44936 | H47: -3341400 | I47: 6500200 | J47: 6332766.7 | K47: {=_xlfn.NORM.S.INV(0.99)*SQRT(MMULT(MMULT(H47:J47,$C$7:$E$9),TRANSPOSE(H47:J47)))} -> 301005.06
B48: 44567 | C48: -0.0022222222 | D48: 0.0053567602 | E48: 0.0061652802 | G48: 44937 | H48: -3389400 | I48: 6405000 | J48: 6361580 | K48: {=_xlfn.NORM.S.INV(0.99)*SQRT(MMULT(MMULT(H48:J48,$C$7:$E$9),TRANSPOSE(H48:J48)))} -> 298162.87
B49: 44568 | C49: -0.010022272 | D49: 0.0053282182 | E49: 0.0015930989 | G49: 44938 | H49: -3407400 | I49: 6526800 | J49: 6378261.1 | K49: {=_xlfn.NORM.S.INV(0.99)*SQRT(MMULT(MMULT(H49:J49,$C$7:$E$9),TRANSPOSE(H49:J49)))} -> 302324.75
B50: 44571 | C50: -0.020568857 | D50: 0.006995972 | E50: 0.0080753996 | G50: 44939 | H50: -3418800 | I50: 6484800 | J50: 6407074 | K50: {=_xlfn.NORM.S.INV(0.99)*SQRT(MMULT(MMULT(H50:J50,$C$7:$E$9),TRANSPOSE(H50:J50)))} -> 301378.55
B51: 44572 | C51: 0.0022969647 | D51: -0.0042105263 | E51: 0.0037624577 | G51: 44943 | H51: -3438000 | I51: 6445600 | J51: 6491237.6 | K51: {=_xlfn.NORM.S.INV(0.99)*SQRT(MMULT(MMULT(H51:J51,$C$7:$E$9),TRANSPOSE(H51:J51)))} -> 301408.91
B52: 44573 | C52: -0.0031101653 | D52: 0.014164905 | E52: -0.0096733463 | G52: 44944 | H52: -3373200 | I52: 6538000 | J52: 6425271.6 | K52: {=_xlfn.NORM.S.INV(0.99)*SQRT(MMULT(MMULT(H52:J52,$C$7:$E$9),TRANSPOSE(H52:J52)))} -> 303613.88
B53: 44574 | C53: -0.0032840722 | D53: 0.0012507817 | E53: 0.0073259398 | G53: 44945 | H53: -3369600 | I53: 6508600 | J53: 6407832 | K53: {=_xlfn.NORM.S.INV(0.99)*SQRT(MMULT(MMULT(H53:J53,$C$7:$E$9),TRANSPOSE(H53:J53)))} -> 302384.86
B54: 44575 | C54: -0.0046128501 | D54: -0.0035394545 | E54: -0.0021817854 | G54: 44946 | H54: -3361200 | I54: 6608000 | J54: 6405557.6 | K54: {=_xlfn.NORM.S.INV(0.99)*SQRT(MMULT(MMULT(H54:J54,$C$7:$E$9),TRANSPOSE(H54:J54)))} -> 305630.05
B55: 44579 | C55: 0.012744124 | D55: 0.022565817 | E55: -0.0026725713 | G55: 44949 | H55: -3395400 | I55: 6592600 | J55: 6477589.6 | K55: {=_xlfn.NORM.S.INV(0.99)*SQRT(MMULT(MMULT(H55:J55,$C$7:$E$9),TRANSPOSE(H55:J55)))} -> 306154.38
B56: 44580 | C56: -0.018140219 | D56: -0.0040866367 | E56: -0.0077952834 | G56: 44950 | H56: -3376800 | I56: 6704600 | J56: 6449535.2 | K56: {=_xlfn.NORM.S.INV(0.99)*SQRT(MMULT(MMULT(H56:J56,$C$7:$E$9),TRANSPOSE(H56:J56)))} -> 309438.67
B57: 44581 | C57: 0.0086551265 | D57: -0.0041034058 | E57: -0.00085937648 | G57: 44951 | H57: -3381000 | I57: 6694800 | J57: 6467732.8 | K57: {=_xlfn.NORM.S.INV(0.99)*SQRT(MMULT(MMULT(H57:J57,$C$7:$E$9),TRANSPOSE(H57:J57)))} -> 309396.26
B58: 44582 | C58: -0.001320132 | D58: -0.0014421096 | E58: -0.018675463 | G58: 44952 | H58: -3294000 | I58: 6721400 | J58: 6269075.2 | K58: {=_xlfn.NORM.S.INV(0.99)*SQRT(MMULT(MMULT(H58:J58,$C$7:$E$9),TRANSPOSE(H58:J58)))} -> 307438.88
... B263: 44883 | C263: 0.0091008373 | D263: 0.015640767 | E263: 0.030728369 | G263: 45254 | H263: -3014400 | I263: 7185500 | J263: 6943200 | K263: {=_xlfn.NORM.S.INV(0.99)*SQRT(MMULT(MMULT(H263:J263,$C$7:$E$9),TRANSPOSE(H263:J263)))} -> 335294.3
G264: 45257 | H264: -3006600 | I264: 7213500 | J264: 6877600 | K264: {=_xlfn.NORM.S.INV(0.99)*SQRT(MMULT(MMULT(H264:J264,$C$7:$E$9),TRANSPOSE(H264:J264)))} -> 335158.57
G265: 45258 | H265: -2982000 | I265: 7231000 | J265: 6822400 | K265: {=_xlfn.NORM.S.INV(0.99)*SQRT(MMULT(MMULT(H265:J265,$C$7:$E$9),TRANSPOSE(H265:J265)))} -> 334955.16
G266: 45259 | H266: -2973900 | I266: 7192500 | J266: 6787200 | K266: {=_xlfn.NORM.S.INV(0.99)*SQRT(MMULT(MMULT(H266:J266,$C$7:$E$9),TRANSPOSE(H266:J266)))} -> 333145.45
G267: 45260 | H267: -2980500 | I267: 7227500 | J267: 6809600 | K267: {=_xlfn.NORM.S.INV(0.99)*SQRT(MMULT(MMULT(H267:J267,$C$7:$E$9),TRANSPOSE(H267:J267)))} -> 334634.98
G268: 45261 | H268: -2968500 | I268: 6883800 | J268: 6830400 | K268: {=_xlfn.NORM.S.INV(0.99)*SQRT(MMULT(MMULT(H268:J268,$C$7:$E$9),TRANSPOSE(H268:J268)))} -> 323771.42
...

Sheet VaR Backtesting
B5: Date | C5: Portfolio w | D5: Pnl | E5: VaR_π_AN | F5: CHECKS
B6: 44886 | C6: =SUM('Asset-Normal Portfolio VaR'!H14:J14) -> 8532231.2 | I6: ALL | J6: FROM 2024
B7: 44887 | C7: =SUM('Asset-Normal Portfolio VaR'!H15:J15) -> 8576966.7 | D7: =C7-C6 -> 44735.52 | E7: 272340.7 | F7: =IF(-(D7)<E7,"YES","NO") -> YES | H7: P(VaR > PnL) | I7: =H33/H32 -> 0.98398577 | J7: =I33/I32 -> 0.98275862
B8: 44888 | C8: =SUM('Asset-Normal Portfolio VaR'!H16:J16) -> 8547106.8 | D8: =C8-C7 -> -29859.92 | E8: 273561.66 | F8: =IF(-(D8)<E8,"YES","NO") -> YES
B9: 44890 | C9: =SUM('Asset-Normal Portfolio VaR'!H17:J17) -> 8686213.6 | D9: =C9-C8 -> 139106.8 | E9: 276950.6 | F9: =IF(-(D9)<E9,"YES","NO") -> YES | H9: Comments
B10: 44893 | C10: =SUM('Asset-Normal Portfolio VaR'!H18:J18) -> 8774168.8 | D10: =C10-C9 -> 87955.2 | E10: 279889.55 | F10: =IF(-(D10)<E10,"YES","NO") -> YES | H10: The result in both cases is not in line with the expectation
B11: 44894 | C11: =SUM('Asset-Normal Portfolio VaR'!H19:J19) -> 8894685.6 | D11: =C11-C10 -> 120516.8 | E11: 281855.5 | F11: =IF(-(D11)<E11,"YES","NO") -> YES
B12: 44895 | C12: =SUM('Asset-Normal Portfolio VaR'!H20:J20) -> 8867824 | D12: =C12-C11 -> -26861.6 | E12: 281493.64 | F12: =IF(-(D12)<E12,"YES","NO") -> YES
B13: 44896 | C13: =SUM('Asset-Normal Portfolio VaR'!H21:J21) -> 8913744.4 | D13: =C13-C12 -> 45920.4 | E13: 283596.8 | F13: =IF(-(D13)<E13,"YES","NO") -> YES
B14: 44897 | C14: =SUM('Asset-Normal Portfolio VaR'!H22:J22) -> 8915977.2 | D14: =C14-C13 -> 2232.8 | E14: 283022.95 | F14: =IF(-(D14)<E14,"YES","NO") -> YES
B15: 44900 | C15: =SUM('Asset-Normal Portfolio VaR'!H23:J23) -> 9148844.8 | D15: =C15-C14 -> 232867.6 | E15: 287175.98 | F15: =IF(-(D15)<E15,"YES","NO") -> YES
B16: 44901 | C16: =SUM('Asset-Normal Portfolio VaR'!H24:J24) -> 9068816 | D16: =C16-C15 -> -80028.8 | E16: 285437.03 | F16: =IF(-(D16)<E16,"YES","NO") -> YES
B17: 44902 | C17: =SUM('Asset-Normal Portfolio VaR'!H25:J25) -> 9170728 | D17: =C17-C16 -> 101912 | E17: 286223 | F17: =IF(-(D17)<E17,"YES","NO") -> YES
B18: 44903 | C18: =SUM('Asset-Normal Portfolio VaR'!H26:J26) -> 9235932.8 | D18: =C18-C17 -> 65204.8 | E18: 288981.71 | F18: =IF(-(D18)<E18,"YES","NO") -> YES
B19: 44904 | C19: =SUM('Asset-Normal Portfolio VaR'!H27:J27) -> 9296981.2 | D19: =C19-C18 -> 61048.4 | E19: 290586.61 | F19: =IF(-(D19)<E19,"YES","NO") -> YES
B20: 44907 | C20: =SUM('Asset-Normal Portfolio VaR'!H28:J28) -> 9180277.6 | D20: =C20-C19 -> -116703.6 | E20: 287685.17 | F20: =IF(-(D20)<E20,"YES","NO") -> YES
B21: 44908 | C21: =SUM('Asset-Normal Portfolio VaR'!H29:J29) -> 9195221.2 | D21: =C21-C20 -> 14943.6 | E21: 288362.85 | F21: =IF(-(D21)<E21,"YES","NO") -> YES
B22: 44909 | C22: =SUM('Asset-Normal Portfolio VaR'!H30:J30) -> 9248865.6 | D22: =C22-C21 -> 53644.4 | E22: 289786.5 | F22: =IF(-(D22)<E22,"YES","NO") -> YES
... B31: 44923 | C31: =SUM('Asset-Normal Portfolio VaR'!H39:J39) -> 9274957.6 | D31: =C31-C30 -> -49346.88 | E31: 290090.03 | F31: =IF(-(D31)<E31,"YES","NO") -> YES
B32: 44924 | C32: =SUM('Asset-Normal Portfolio VaR'!H40:J40) -> 9345988.3 | D32: =C32-C31 -> 71030.72 | E32: 292186.09 | F32: =IF(-(D32)<E32,"YES","NO") -> YES | H32: =COUNTIF(F7:F568, "Yes") + COUNTIF(F7:F568, "No") -> 562 | I32: =COUNTIF(F279:F568, "Yes") + COUNTIF(F279:F568, "No") -> 290
B33: 44925 | C33: =SUM('Asset-Normal Portfolio VaR'!H41:J41) -> 9177474.4 | D33: =C33-C32 -> -168513.92 | E33: 287189.04 | F33: =IF(-(D33)<E33,"YES","NO") -> YES | H33: {=SUMPRODUCT(--(F7:F568="Yes"))} -> 553 | I33: {=SUMPRODUCT(--(F279:F568="Yes"))} -> 285
B34: 44929 | C34: =SUM('Asset-Normal Portfolio VaR'!H42:J42) -> 9510919.2 | D34: =C34-C33 -> 333444.8 | E34: 296805.57 | F34: =IF(-(D34)<E34,"YES","NO") -> YES
B35: 44930 | C35: =SUM('Asset-Normal Portfolio VaR'!H43:J43) -> 9735452.8 | D35: =C35-C34 -> 224533.6 | E35: 305744.11 | F35: =IF(-(D35)<E35,"YES","NO") -> YES
B36: 44931 | C36: =SUM('Asset-Normal Portfolio VaR'!H44:J44) -> 9663803.6 | D36: =C36-C35 -> -71649.2 | E36: 304175.07 | F36: =IF(-(D36)<E36,"YES","NO") -> YES
B37: 44932 | C37: =SUM('Asset-Normal Portfolio VaR'!H45:J45) -> 9813369.1 | D37: =C37-C36 -> 149565.52 | E37: 308511.75 | F37: =IF(-(D37)<E37,"YES","NO") -> YES
B38: 44935 | C38: =SUM('Asset-Normal Portfolio VaR'!H46:J46) -> 9702690.4 | D38: =C38-C37 -> -110678.72 | E38: 305899.13 | F38: =IF(-(D38)<E38,"YES","NO") -> YES
B39: 44936 | C39: =SUM('Asset-Normal Portfolio VaR'!H47:J47) -> 9491566.7 | D39: =C39-C38 -> -211123.68 | E39: 301005.06 | F39: =IF(-(D39)<E39,"YES","NO") -> YES
B40: 44937 | C40: =SUM('Asset-Normal Portfolio VaR'!H48:J48) -> 9377180 | D40: =C40-C39 -> -114386.72 | E40: 298162.87 | F40: =IF(-(D40)<E40,"YES","NO") -> YES
B41: 44938 | C41: =SUM('Asset-Normal Portfolio VaR'!H49:J49) -> 9497661.1 | D41: =C41-C40 -> 120481.12 | E41: 302324.75 | F41: =IF(-(D41)<E41,"YES","NO") -> YES
B42: 44939 | C42: =SUM('Asset-Normal Portfolio VaR'!H50:J50) -> 9473074 | D42: =C42-C41 -> -24587.12 | E42: 301378.55 | F42: =IF(-(D42)<E42,"YES","NO") -> YES
B43: 44943 | C43: =SUM('Asset-Normal Portfolio VaR'!H51:J51) -> 9498837.6 | D43: =C43-C42 -> 25763.6 | E43: 301408.91 | F43: =IF(-(D43)<E43,"YES","NO") -> YES
B44: 44944 | C44: =SUM('Asset-Normal Portfolio VaR'!H52:J52) -> 9590071.6 | D44: =C44-C43 -> 91234 | E44: 303613.88 | F44: =IF(-(D44)<E44,"YES","NO") -> YES
B45: 44945 | C45: =SUM('Asset-Normal Portfolio VaR'!H53:J53) -> 9546832 | D45: =C45-C44 -> -43239.6 | E45: 302384.86 | F45: =IF(-(D45)<E45,"YES","NO") -> YES
... B568: 45729 | C568: =SUM('Asset-Normal Portfolio VaR'!H576:J576) -> 15342700 | D568: =C568-C567 -> 8600 | E568: 454128.38 | F568: =IF(-(D568)<E568,"YES","NO") -> YES

Sheet Component & Relative VaR
B4: Var - Cov Matrix | C4: NESN | D4: SREN | E4: NOVN
B5: NESN | C5: 0.00012892024 | D5: 4.3332926e-05 | E5: 6.3046607e-05
B6: SREN | C6: 4.3332926e-05 | D6: 0.00025221438 | E6: 5.0775455e-05
B7: NOVN | C7: 6.3046607e-05 | D7: 5.0775455e-05 | E7: 0.0001250704
B11: Date | C11: VaR_NESN | D11: Value_SREN | E11: Value_NOVN | F11: VaR_π_AN | G11: Portfolio w | I11: MVaR_NESN | J11: MVaR_SREN | K11: MVaR_NOVN | L11: CVaR_NESN | M11: CVaR_SREN | N11: CVaR_NPVN | O11: RCVaR_NESN | P11: RCVaR_SREN | Q11: RCVaR_NOVN
B12: 44886 | C12: -3364200 | D12: 5608400 | E12: 6288031.2 | F12: 271457.68 | G12: 8532231.2 | I12: {=TRANSPOSE(F12*MMULT($C$5:$E$7,TRANSPOSE(C12:E12)/MMULT(MMULT(C12:E12,$C$5:$E$7),TRANSPOSE(C12:E12))))} -> 0.0041019971 | J12: 0.031659358 | K12: 0.017127663 | L12: =C12*I12 -> -13799.939 | M12: =D12*J12 -> 177558.34 | N12: =E12*K12 -> 107699.28 | O12: =L12/F12 -> -0.050836427 | P12: =M12/F12 -> 0.65409217 | Q12: =N12/F12 -> 0.39674426
B13: 44887 | C13: -3368400 | D13: 5612600 | E13: 6332766.7 | F13: 272340.7 | G13: 8576966.7 | I13: {=TRANSPOSE(F13*MMULT($C$5:$E$7,TRANSPOSE(C13:E13)/MMULT(MMULT(C13:E13,$C$5:$E$7),TRANSPOSE(C13:E13))))} -> 0.0041376006 | J13: 0.031619279 | K13: 0.017182289 | L13: =C13*I13 -> -13937.094 | M13: =D13*J13 -> 177466.36 | N13: =E13*K13 -> 108811.43 | O13: =L13/F13 -> -0.051175215 | P13: =M13/F13 -> 0.65163365 | Q13: =N13/F13 -> 0.39954156
B14: 44888 | C14: -3387600 | D14: 5713400 | E14: 6221306.8 | F14: 273561.66 | G14: 8547106.8 | I14: {=TRANSPOSE(F14*MMULT($C$5:$E$7,TRANSPOSE(C14:E14)/MMULT(MMULT(C14:E14,$C$5:$E$7),TRANSPOSE(C14:E14))))} -> 0.0040175578 | J14: 0.031852685 | K14: 0.016907124 | L14: =C14*I14 -> -13609.879 | M14: =D14*J14 -> 181987.13 | N14: =E14*K14 -> 105184.41 | O14: =L14/F14 -> -0.049750681 | P14: =M14/F14 -> 0.66525087 | Q14: =N14/F14 -> 0.38449981
B15: 44890 | C15: -3390000 | D15: 5780600 | E15: 6295613.6 | F15: 276950.6 | G15: 8686213.6 | I15: {=TRANSPOSE(F15*MMULT($C$5:$E$7,TRANSPOSE(C15:E15)/MMULT(MMULT(C15:E15,$C$5:$E$7),TRANSPOSE(C15:E15))))} -> 0.0041107988 | J15: 0.031865808 | K15: 0.016945563 | L15: =C15*I15 -> -13935.608 | M15: =D15*J15 -> 184203.49 | N15: =E15*K15 -> 106682.72 | O15: =L15/F15 -> -0.050318027 | P15: =M15/F15 -> 0.66511316 | Q15: =N15/F15 -> 0.38520487
B16: 44893 | C16: -3405000 | D16: 5864600 | E16: 6314568.8 | F16: 279889.55 | G16: 8774168.8 | I16: {=TRANSPOSE(F16*MMULT($C$5:$E$7,TRANSPOSE(C16:E16)/MMULT(MMULT(C16:E16,$C$5:$E$7),TRANSPOSE(C16:E16))))} -> 0.0041237313 | J16: 0.031946895 | K16: 0.016877652 | L16: =C16*I16 -> -14041.305 | M16: =D16*J16 -> 187355.76 | N16: =E16*K16 -> 106575.1 | O16: =L16/F16 -> -0.050167307 | P16: =M16/F16 -> 0.66939176 | Q16: =N16/F16 -> 0.38077555
B17: 44894 | C17: -3337800 | D17: 5916400 | E17: 6316085.6 | F17: 281855.5 | G17: 8894685.6 | I17: {=TRANSPOSE(F17*MMULT($C$5:$E$7,TRANSPOSE(C17:E17)/MMULT(MMULT(C17:E17,$C$5:$E$7),TRANSPOSE(C17:E17))))} -> 0.0043062499 | J17: 0.03203231 | K17: 0.016895424 | L17: =C17*I17 -> -14373.401 | M17: =D17*J17 -> 189515.96 | N17: =E17*K17 -> 106712.94 | O17: =L17/F17 -> -0.050995638 | P17: =M17/F17 -> 0.67238695 | Q17: =N17/F17 -> 0.37860869
B18: 44895 | C18: -3370200 | D18: 5895400 | E18: 6342624 | F18: 281493.64 | G18: 8867824 | I18: {=TRANSPOSE(F18*MMULT($C$5:$E$7,TRANSPOSE(C18:E18)/MMULT(MMULT(C18:E18,$C$5:$E$7),TRANSPOSE(C18:E18))))} -> 0.0042461522 | J18: 0.031970573 | K18: 0.016921183 | L18: =C18*I18 -> -14310.382 | M18: =D18*J18 -> 188479.32 | N18: =E18*K18 -> 107324.7 | O18: =L18/F18 -> -0.050837319 | P18: =M18/F18 -> 0.66956865 | Q18: =N18/F18 -> 0.38126866
B19: 44896 | C19: -3411600 | D19: 5948600 | E19: 6376744.4 | F19: 283596.8 | G19: 8913744.4 | I19: {=TRANSPOSE(F19*MMULT($C$5:$E$7,TRANSPOSE(C19:E19)/MMULT(MMULT(C19:E19,$C$5:$E$7),TRANSPOSE(C19:E19))))} -> 0.0041978541 | J19: 0.031988359 | K19: 0.016878871 | L19: =C19*I19 -> -14321.399 | M19: =D19*J19 -> 190285.95 | N19: =E19*K19 -> 107632.25 | O19: =L19/F19 -> -0.050499157 | P19: =M19/F19 -> 0.67097355 | Q19: =N19/F19 -> 0.3795256
B20: 44897 | C20: -3390000 | D20: 5926200 | E20: 6379777.2 | F20: 283022.95 | G20: 8915977.2 | I20: {=TRANSPOSE(F20*MMULT($C$5:$E$7,TRANSPOSE(C20:E20)/MMULT(MMULT(C20:E20,$C$5:$E$7),TRANSPOSE(C20:E20))))} -> 0.004244709 | J20: 0.031966029 | K20: 0.016924639 | L20: =C20*I20 -> -14389.564 | M20: =D20*J20 -> 189437.08 | N20: =E20*K20 -> 107975.43 | O20: =L20/F20 -> -0.050842392 | P20: =M20/F20 -> 0.66933472 | Q20: =N20/F20 -> 0.38150767
B21: 44900 | C21: -3339000 | D21: 5982200 | E21: 6505644.8 | F21: 287175.98 | G21: 9148844.8 | I21: {=TRANSPOSE(F21*MMULT($C$5:$E$7,TRANSPOSE(C21:E21)/MMULT(MMULT(C21:E21,$C$5:$E$7),TRANSPOSE(C21:E21))))} -> 0.004502507 | J21: 0.031932006 | K21: 0.017090728 | L21: =C21*I21 -> -15033.871 | M21: =D21*J21 -> 191023.64 | N21: =E21*K21 -> 111186.2 | O21: =L21/F21 -> -0.052350726 | P21: =M21/F21 -> 0.66517975 | Q21: =N21/F21 -> 0.38717098
B22: 44901 | C22: -3347400 | D22: 5950000 | E22: 6466216 | F22: 285437.03 | G22: 9068816 | I22: {=TRANSPOSE(F22*MMULT($C$5:$E$7,TRANSPOSE(C22:E22)/MMULT(MMULT(C22:E22,$C$5:$E$7),TRANSPOSE(C22:E22))))} -> 0.0044358179 | J22: 0.031927703 | K22: 0.01706031 | L22: =C22*I22 -> -14848.457 | M22: =D22*J22 -> 189969.84 | N22: =E22*K22 -> 110315.65 | O22: =L22/F22 -> -0.05202008 | P22: =M22/F22 -> 0.66554027 | Q22: =N22/F22 -> 0.38647981
B23: 44902 | C23: -3277800 | D23: 5944400 | E23: 6504128 | F23: 286223 | G23: 9170728 | I23: {=TRANSPOSE(F23*MMULT($C$5:$E$7,TRANSPOSE(C23:E23)/MMULT(MMULT(C23:E23,$C$5:$E$7),TRANSPOSE(C23:E23))))} -> 0.0046339013 | J23: 0.031906747 | K23: 0.017180709 | L23: =C23*I23 -> -15189.002 | M23: =D23*J23 -> 189666.47 | N23: =E23*K23 -> 111745.53 | O23: =L23/F23 -> -0.05306702 | P23: =M23/F23 -> 0.66265279 | Q23: =N23/F23 -> 0.39041423
... B40: 44929 | C40: -3267600 | D40: 6270600 | E40: 6507919.2 | F40: 296805.57 | G40: 9510919.2 | I40: {=TRANSPOSE(F40*MMULT($C$5:$E$7,TRANSPOSE(C40:E40)/MMULT(MMULT(C40:E40,$C$5:$E$7),TRANSPOSE(C40:E40))))} -> 0.004754754 | J40: 0.032280823 | K40: 0.01689051 | L40: =C40*I40 -> -15536.634 | M40: =D40*J40 -> 202420.13 | N40: =E40*K40 -> 109922.08 | O40: =L40/F40 -> -0.052346168 | P40: =M40/F40 -> 0.68199572 | Q40: =N40/F40 -> 0.37035045
B41: 44930 | C41: -3324000 | D41: 6557600 | E41: 6501852.8 | F41: 305744.11 | G41: 9735452.8 | I41: {=TRANSPOSE(F41*MMULT($C$5:$E$7,TRANSPOSE(C41:E41)/MMULT(MMULT(C41:E41,$C$5:$E$7),TRANSPOSE(C41:E41))))} -> 0.0047004093 | J41: 0.032569645 | K41: 0.016578284 | L41: =C41*I41 -> -15624.161 | M41: =D41*J41 -> 213578.71 | N41: =E41*K41 -> 107789.56 | O41: =L41/F41 -> -0.051102082 | P41: =M41/F41 -> 0.69855379 | Q41: =N41/F41 -> 0.35254829 | S41: Comments
B42: 44931 | C42: -3314400 | D42: 6540800 | E42: 6437403.6 | F42: 304175.07 | G42: 9663803.6 | I42: {=TRANSPOSE(F42*MMULT($C$5:$E$7,TRANSPOSE(C42:E42)/MMULT(MMULT(C42:E42,$C$5:$E$7),TRANSPOSE(C42:E42))))} -> 0.0046614287 | J42: 0.03261144 | K42: 0.016515976 | L42: =C42*I42 -> -15449.839 | M42: =D42*J42 -> 213304.91 | N42: =E42*K42 -> 106320 | O42: =L42/F42 -> -0.050792589 | P42: =M42/F42 -> 0.70125703 | Q42: =N42/F42 -> 0.34953556 | S42: Relative Component VaR's for each asset heavily depend on the value of the positions and it's MVaR. Since SREN and NOVN has similar values and MVaRs, their RCVaRs are similar. On the other hand, NESN has low weight and low MVaR.
B43: 44932 | C43: -3333000 | D43: 6643000 | E43: 6503369.1 | F43: 308511.75 | G43: 9813369.1 | I43: {=TRANSPOSE(F43*MMULT($C$5:$E$7,TRANSPOSE(C43:E43)/MMULT(MMULT(C43:E43,$C$5:$E$7),TRANSPOSE(C43:E43))))} -> 0.0047044819 | J43: 0.032649812 | K43: 0.016499 | L43: =C43*I43 -> -15680.038 | M43: =D43*J43 -> 216892.7 | N43: =E43*K43 -> 107299.09 | O43: =L43/F43 -> -0.050824768 | P43: =M43/F43 -> 0.70302897 | Q43: =N43/F43 -> 0.34779579
B44: 44935 | C44: -3348600 | D44: 6582800 | E44: 6468490.4 | F44: 305899.13 | G44: 9702690.4 | I44: {=TRANSPOSE(F44*MMULT($C$5:$E$7,TRANSPOSE(C44:E44)/MMULT(MMULT(C44:E44,$C$5:$E$7),TRANSPOSE(C44:E44))))} -> 0.0046240256 | J44: 0.032616757 | K44: 0.01649126 | L44: =C44*I44 -> -15484.012 | M44: =D44*J44 -> 214709.59 | N44: =E44*K44 -> 106673.56 | O44: =L44/F44 -> -0.050618033 | P44: =M44/F44 -> 0.70189669 | Q44: =N44/F44 -> 0.34872135
B45: 44936 | C45: -3341400 | D45: 6500200 | E45: 6332766.7 | F45: 301005.06 | G45: 9491566.7 | I45: {=TRANSPOSE(F45*MMULT($C$5:$E$7,TRANSPOSE(C45:E45)/MMULT(MMULT(C45:E45,$C$5:$E$7),TRANSPOSE(C45:E45))))} -> 0.004497695 | J45: 0.032654218 | K45: 0.016386947 | L45: =C45*I45 -> -15028.598 | M45: =D45*J45 -> 212258.95 | N45: =E45*K45 -> 103774.71 | O45: =L45/F45 -> -0.049928058 | P45: =M45/F45 -> 0.70516737 | Q45: =N45/F45 -> 0.34476069
B46: 44937 | C46: -3389400 | D46: 6405000 | E46: 6361580 | F46: 298162.87 | G46: 9377180 | I46: {=TRANSPOSE(F46*MMULT($C$5:$E$7,TRANSPOSE(C46:E46)/MMULT(MMULT(C46:E46,$C$5:$E$7),TRANSPOSE(C46:E46))))} -> 0.0043863432 | J46: 0.032518475 | K46: 0.016465896 | L46: =C46*I46 -> -14867.072 | M46: =D46*J46 -> 208280.83 | N46: =E46*K46 -> 104749.12 | O46: =L46/F46 -> -0.04986225 | P46: =M46/F46 -> 0.69854716 | Q46: =N46/F46 -> 0.35131509
B47: 44938 | C47: -3407400 | D47: 6526800 | E47: 6378261.1 | F47: 302324.75 | G47: 9497661.1 | I47: {=TRANSPOSE(F47*MMULT($C$5:$E$7,TRANSPOSE(C47:E47)/MMULT(MMULT(C47:E47,$C$5:$E$7),TRANSPOSE(C47:E47))))} -> 0.0043977259 | J47: 0.032621928 | K47: 0.016366962 | L47: =C47*I47 -> -14984.811 | M47: =D47*J47 -> 212916.8 | N47: =E47*K47 -> 104392.76 | O47: =L47/F47 -> -0.049565282 | P47: =M47/F47 -> 0.7042652 | Q47: =N47/F47 -> 0.34530008
B48: 44939 | C48: -3418800 | D48: 6484800 | E48: 6407074 | F48: 301378.55 | G48: 9473074 | I48: {=TRANSPOSE(F48*MMULT($C$5:$E$7,TRANSPOSE(C48:E48)/MMULT(MMULT(C48:E48,$C$5:$E$7),TRANSPOSE(C48:E48))))} -> 0.0043850798 | J48: 0.032551527 | K48: 0.016431857 | L48: =C48*I48 -> -14991.711 | M48: =D48*J48 -> 211090.14 | N48: =E48*K48 -> 105280.12 | O48: =L48/F48 -> -0.049743788 | P48: =M48/F48 -> 0.70041527 | Q48: =N48/F48 -> 0.34932852
B49: 44943 | C49: -3438000 | D49: 6445600 | E49: 6491237.6 | F49: 301408.91 | G49: 9498837.6 | I49: {=TRANSPOSE(F49*MMULT($C$5:$E$7,TRANSPOSE(C49:E49)/MMULT(MMULT(C49:E49,$C$5:$E$7),TRANSPOSE(C49:E49))))} -> 0.0044049691 | J49: 0.03243252 | K49: 0.016561733 | L49: =C49*I49 -> -15144.284 | M49: =D49*J49 -> 209047.05 | N49: =E49*K49 -> 107506.15 | O49: =L49/F49 -> -0.050244977 | P49: =M49/F49 -> 0.69356625 | Q49: =N49/F49 -> 0.35667873
B50: 44944 | C50: -3373200 | D50: 6538000 | E50: 6425271.6 | F50: 303613.88 | G50: 9590071.6 | I50: {=TRANSPOSE(F50*MMULT($C$5:$E$7,TRANSPOSE(C50:E50)/MMULT(MMULT(C50:E50,$C$5:$E$7),TRANSPOSE(C50:E50))))} -> 0.0045191261 | J50: 0.032602732 | K50: 0.016450843 | L50: =C50*I50 -> -15243.916 | M50: =D50*J50 -> 213156.66 | N50: =E50*K50 -> 105701.14 | O50: =L50/F50 -> -0.050208231 | P50: =M50/F50 -> 0.70206494 | Q50: =N50/F50 -> 0.34814329
B51: 44945 | C51: -3369600 | D51: 6508600 | E51: 6407832 | F51: 302384.86 | G51: 9546832 | I51: {=TRANSPOSE(F51*MMULT($C$5:$E$7,TRANSPOSE(C51:E51)/MMULT(MMULT(C51:E51,$C$5:$E$7),TRANSPOSE(C51:E51))))} -> 0.0045033209 | J51: 0.032589477 | K51: 0.016456014 | L51: =C51*I51 -> -15174.39 | M51: =D51*J51 -> 212111.87 | N51: =E51*K51 -> 105447.38 | O51: =L51/F51 -> -0.050182374 | P51: =M51/F51 -> 0.70146327 | Q51: =N51/F51 -> 0.3487191
B52: 44946 | C52: -3361200 | D52: 6608000 | E52: 6405557.6 | F52: 305630.05 | G52: 9652357.6 | I52: {=TRANSPOSE(F52*MMULT($C$5:$E$7,TRANSPOSE(C52:E52)/MMULT(MMULT(C52:E52,$C$5:$E$7),TRANSPOSE(C52:E52))))} -> 0.0045484119 | J52: 0.032691767 | K52: 0.016374995 | L52: =C52*I52 -> -15288.122 | M52: =D52*J52 -> 216027.19 | N52: =E52*K52 -> 104890.97 | O52: =L52/F52 -> -0.050021659 | P52: =M52/F52 -> 0.70682578 | Q52: =N52/F52 -> 0.34319588
B53: 44949 | C53: -3395400 | D53: 6592600 | E53: 6477589.6 | F53: 306154.38 | G53: 9674789.6 | I53: {=TRANSPOSE(F53*MMULT($C$5:$E$7,TRANSPOSE(C53:E53)/MMULT(MMULT(C53:E53,$C$5:$E$7),TRANSPOSE(C53:E53))))} -> 0.0045311644 | J53: 0.032605574 | K53: 0.016454266 | L53: =C53*I53 -> -15385.116 | M53: =D53*J53 -> 214955.51 | N53: =E53*K53 -> 106583.99 | O53: =L53/F53 -> -0.050252803 | P53: =M53/F53 -> 0.70211476 | Q53: =N53/F53 -> 0.34813804
B54: 44950 | C54: -3376800 | D54: 6704600 | E54: 6449535.2 | F54: 309438.67 | G54: 9777335.2 | I54: {=TRANSPOSE(F54*MMULT($C$5:$E$7,TRANSPOSE(C54:E54)/MMULT(MMULT(C54:E54,$C$5:$E$7),TRANSPOSE(C54:E54))))} -> 0.004578957 | J54: 0.032742731 | K54: 0.016338228 | L54: =C54*I54 -> -15462.222 | M54: =D54*J54 -> 219526.92 | N54: =E54*K54 -> 105373.98 | O54: =L54/F54 -> -0.049968615 | P54: =M54/F54 -> 0.70943595 | Q54: =N54/F54 -> 0.34053267
... B574: 45729 | C574: -2677200 | D574: 10265500 | E574: 7754400 | F574: 454128.38 | G574: 15342700 | I574: {=TRANSPOSE(F574*MMULT($C$5:$E$7,TRANSPOSE(C574:E574)/MMULT(MMULT(C574:E574,$C$5:$E$7),TRANSPOSE(C574:E574))))} -> 0.0070141383 | J574: 0.034164295 | K574: 0.015757901 | L574: =C574*I574 -> -18778.251 | M574: =D574*J574 -> 350713.57 | N574: =E574*K574 -> 122193.06 | O574: =L574/F574 -> -0.041350094 | P574: =M574/F574 -> 0.77227846 | Q574: =N574/F574 -> 0.26907163

Sheet Incremental VaR Analysis
B3: Date | C3: MVaR_NESN | D3: MVaR_SREN | E3: MVaR_NOVN
B4: 45729 | C4: 0.70722627 | D4: 1.0153997 | E4: 0.45989915
B6: buy NESN | C6: buy SREN | D6: sell NOVN | H6: Comments
B7: 2000000 | C7: 1000000 | D7: -1000000 | H7: Since VaR_π_AN_After is much bigger than VaR_π_AN + IVAR the estimation is not good.
B9: IVAR | C9: {=MMULT(C4:E4,TRANSPOSE(B7:D7))} -> 1969953.1
B12: VaR_π_AN | D12: 454128.38
B13: VaR_π_AN + IVAR | D13: =D12+C9 -> 2424081.5
C16: NESN | D16: SREN | E16: NOVN
B17: Position_Before | C17: -30000 | D17: 70000 | E17: 80000
B18: Position_After | C18: =(B7/Data!C1470+C17) -> -7588.5253 | D18: =(D17/Data!D1470+C7) -> 1000477.3 | E18: =(D7/Data!E1470+E17) -> 69683.277
B21: Var - Cov Matrix | C21: NESN | D21: SREN | E21: NOVN
B22: NESN | C22: 0.00012892024 | D22: 4.3332926e-05 | E22: 6.3046607e-05
B23: SREN | C23: 4.3332926e-05 | D23: 0.00025221438 | E23: 5.0775455e-05
B24: NOVN | C24: 6.3046607e-05 | D24: 5.0775455e-05 | E24: 0.0001250704
B27: Date | C27: Value_NESN | D27: Value_SREN | E27: Value_NOVN | F27: VaR_π_AN_After
B28: 45729 | C28: =B7+'Asset-Normal Portfolio VaR'!H576 -> -677200 | D28: =C7+'Asset-Normal Portfolio VaR'!I576 -> 11265500 | E28: =D7+'Asset-Normal Portfolio VaR'!J576 -> 6754400 | F28: {=_xlfn.NORM.S.INV(0.99)*SQRT(MMULT(MMULT(C28:E28,C22:E24),TRANSPOSE(C28:E28)))} -> 489436.3
B30: The VaR is higher this indicates This indicates that the trade has increased the portfolio's
B31: overall risk exposure, likely due to higher individual volatilities or reduced diversification
B32: benefits in the new holdings.

Sheet Systematic Risk & Beta Analysis
B4: Date | C4: R_NESN | D4: R_SREN | E4: R_NOVN | F4: SMI | H4: β_NESN | I4: β_SREN | J4: β_NOVN
B5: 43543 | C5: 0.0046728972 | D5: -0.0020036065 | E5: -0.001715211 | F5: 0.00305 | H5: =_xlfn.COVARIANCE.S($F$5:$F$1263,C5:C1263)/_xlfn.VAR.S($F$5:$F$1263) -> 0.75702749 | I5: =_xlfn.COVARIANCE.S($F$5:$F$1263,D5:D1263)/_xlfn.VAR.S($F$5:$F$1263) -> 1.1142744 | J5: =_xlfn.COVARIANCE.S($F$5:$F$1263,E5:E1263)/_xlfn.VAR.S($F$5:$F$1263) -> 0.90128563
B6: 43544 | C6: 0.00063424947 | D6: -0.017667135 | E6: -0.0025774293 | F6: -0.00657
B7: 43545 | C7: 0.0082400169 | D7: -0.0024524831 | E7: 0.003014784 | F7: -0.00098
B8: 43546 | C8: -0.016554904 | D8: -0.012087687 | E8: -0.0012880972 | F8: -0.01424 | H8: Comments
B9: 43549 | C9: 0.0021308332 | D9: 0.0020738283 | E9: -0.0055891161 | F9: -0.00149 | H9: SREN shown an high betas in the portfolio, indicating elevated systematic risk within the portfolio
B10: 43550 | C10: 0.012119923 | D10: -0.0012417219 | E10: 0.019455373 | F10: 0.00901 | H10: and greater exposure to overall market fluctuations. In contrast, NESN shows the lowest beta in the portfolio,
B11: 43551 | C11: 0.0010504202 | D11: 0.0031081641 | E11: 0.0010601707 | F11: 0.00014 | H11: suggesting it contributes less market-related risk and may provide a defensive component
B12: 43552 | C12: -0.0010493179 | D12: 0.00041313778 | E12: 0.0099555309 | F12: 0.00163
B13: 43553 | C13: -0.0031512605 | D13: 0.0043361553 | E13: 0.0044042682 | F13: 0.00765
B14: 43556 | C14: -0.0028451001 | D14: 0.0096628289 | E14: 0.0027146388 | F14: 0.00636
B15: 43557 | C15: 0.0019021452 | D15: 0.0081449807 | E15: -0.012286542 | F15: -0.00016
B16: 43558 | C16: 0.0061174982 | D16: 0.0070692789 | E16: -0.0037950392 | F16: 0.00351
B17: 43559 | C17: -0.0011531607 | D17: 0 | E17: -0.0031747066 | F17: -0.00067
B18: 43560 | C18: 0.004093199 | D18: -0.0040112314 | E18: 0.00063706486 | F18: -0.00236
B19: 43563 | C19: 0.00052262987 | D19: 0.0056383407 | E19: 0.0059409376 | F19: 0.00065
B20: 43564 | C20: 0.0094024237 | D20: -0.0036043252 | E20: 0.011811048 | F20: 0.00365
B21: 43565 | C21: 0.005174912 | D21: -0.0018086817 | E21: -0.030303087 | F21: -0.0027
B22: 43566 | C22: -0.0077224053 | D22: 0.0024159452 | E22: 0.0004863598 | F22: -0.00074
B23: 43567 | C23: -0.0087164055 | D23: -0.0018075919 | E23: -0.015556589 | F23: -0.00674
... B1472: 45729 | C1472: 0.0022461815 | D1472: -0.0033978933 | E1472: 0.0064375454 | F1472: -0.00251

Sheet EWMA & GARCH Volatility Modelin
Q1: 0.0015869045 | R1: =I78 -> -0.00011945422 | S1: =R1^2 -> 1.426931e-08
E3: Estimation | F3: EWMA | G3: GARCH | I3: μ | J3: ω | K3: α | L3: β | M3: α+β+γ | N3: VL | O3: Θ
E4: 45365 | F4: =SQRT(0.94*F597+0.06*E597) -> 0.0035600541 | G4: =SQRT($J$4+$K$4*K597+$L$4*L596) -> 0.0076123692 | I4: =AVERAGE(C7:C821) -> 7.5821755e-05 | J4: 1.5242e-06 | K4: 0.080581 | L4: 0.904946 | M4: =K4+L4+J4/N4 -> 0.98567553 | N4: =SQRT(J4/(1-K4-L4)) -> 0.010262229 | O4: =SUM(M7:M597) -> 2457.6665
B6: Date | C6: SMI | E6: R^2 | F6: σ^2 | G6: σEWMA | I6: Res | J6: Res^2 | K6: Lagged Res^2 | L6: Cond Var | M6: Likelihood | N6: Realised | O6: σGARCH
B7: 44512 | C7: 0.0076455674 | E7: =C7^2 -> 5.8454702e-05 | F7: =E7 -> 5.8454702e-05 | G7: =SQRT(F7) -> 0.0076455674 | I7: =C7-$I$4 -> 0.0075697457 | J7: =I7^2 -> 5.730105e-05 | K7: 3.5850949e-09 | L7: =J4/(1-K4+L4) -> 8.3546878e-07 | M7: =LN(1/SQRT(2*PI()*L7*EXP(-J7/(2*L7)))) -> 23.225075 | N7: =SQRT(J7) -> 0.0075697457 | O7: =SQRT(L7) -> 0.00091403981
B8: 44515 | C8: 8.5562713e-05 | E8: =C8^2 -> 7.3209778e-09 | F8: =E8 -> 7.3209778e-09 | G8: =SQRT(F8) -> 8.5562713e-05 | I8: =C8-$I$4 -> 9.7409578e-06 | J8: =I8^2 -> 9.4886258e-11 | K8: =J7 -> 5.730105e-05 | L8: =$J$4+$K$4*K8+$L$4*L7 -> 6.89763e-06 | M8: =LN(1/SQRT(2*PI()*L8*EXP(-J8/(2*L8)))) -> 5.0232312 | N8: =SQRT(J8) -> 9.7409578e-06 | O8: =SQRT(L8) -> 0.002626334
B9: 44516 | C9: 0.0032135022 | E9: =C9^2 -> 1.0326596e-05 | F9: =E9 -> 1.0326596e-05 | G9: =SQRT(F9) -> 0.0032135022 | I9: =C9-$I$4 -> 0.0031376804 | J9: =I9^2 -> 9.8450383e-06 | K9: =J8 -> 9.4886258e-11 | L9: =$J$4+$K$4*K9+$L$4*L8 -> 7.7661903e-06 | M9: =LN(1/SQRT(2*PI()*L9*EXP(-J9/(2*L9)))) -> 5.2808467 | N9: =SQRT(J9) -> 0.0031376804 | O9: =SQRT(L9) -> 0.0027867885
B10: 44517 | C10: 0.0034090772 | E10: =C10^2 -> 1.1621808e-05 | F10: =E10 -> 1.1621808e-05 | G10: =SQRT(F10) -> 0.0034090772 | I10: =C10-$I$4 -> 0.0033332555 | J10: =I10^2 -> 1.1110592e-05 | K10: =J9 -> 9.8450383e-06 | L10: =$J$4+$K$4*K10+$L$4*L9 -> 9.3455059e-06 | M10: =LN(1/SQRT(2*PI()*L10*EXP(-J10/(2*L10)))) -> 5.1685865 | N10: =SQRT(J10) -> 0.0033332555 | O10: =SQRT(L10) -> 0.003057042
B11: 44518 | C11: -0.0037274033 | E11: =C11^2 -> 1.3893535e-05 | F11: =E11 -> 1.3893535e-05 | G11: =SQRT(F11) -> 0.0037274033 | I11: =C11-$I$4 -> -0.003803225 | J11: =I11^2 -> 1.4464521e-05 | K11: =J10 -> 1.1110592e-05 | L11: =$J$4+$K$4*K11+$L$4*L10 -> 1.0876681e-05 | M11: =LN(1/SQRT(2*PI()*L11*EXP(-J11/(2*L11)))) -> 5.1279725 | N11: =SQRT(J11) -> 0.003803225 | O11: =SQRT(L11) -> 0.0032979813
B12: 44519 | C12: -0.00065103759 | E12: =C12^2 -> 4.2384994e-07 | F12: =E12 -> 4.2384994e-07 | G12: =SQRT(F12) -> 0.00065103759 | I12: =C12-$I$4 -> -0.00072685934 | J12: =I12^2 -> 5.283245e-07 | K12: =J11 -> 1.4464521e-05 | L12: =$J$4+$K$4*K12+$L$4*L11 -> 1.2532574e-05 | M12: =LN(1/SQRT(2*PI()*L12*EXP(-J12/(2*L12)))) -> 4.7351902 | N12: =SQRT(J12) -> 0.00072685934 | O12: =SQRT(L12) -> 0.0035401376
B13: 44522 | C13: -0.0027265896 | E13: =C13^2 -> 7.434291e-06 | F13: =E13 -> 7.434291e-06 | G13: =SQRT(F13) -> 0.0027265896 | I13: =C13-$I$4 -> -0.0028024114 | J13: =I13^2 -> 7.8535095e-06 | K13: =J12 -> 5.283245e-07 | L13: =$J$4+$K$4*K13+$L$4*L12 -> 1.2908076e-05 | M13: =LN(1/SQRT(2*PI()*L13*EXP(-J13/(2*L13)))) -> 4.8619947 | N13: =SQRT(J13) -> 0.0028024114 | O13: =SQRT(L13) -> 0.0035927811
B14: 44523 | C14: -0.011516339 | E14: =C14^2 -> 0.00013262607 | F14: =E14 -> 0.00013262607 | G14: =SQRT(F14) -> 0.011516339 | I14: =C14-$I$4 -> -0.011592161 | J14: =I14^2 -> 0.0001343782 | K14: =J13 -> 7.8535095e-06 | L14: =$J$4+$K$4*K14+$L$4*L13 -> 1.3838155e-05 | M14: =LN(1/SQRT(2*PI()*L14*EXP(-J14/(2*L14)))) -> 7.1027774 | N14: =SQRT(J14) -> 0.011592161 | O14: =SQRT(L14) -> 0.0037199671
B15: 44524 | C15: 0.0023440805 | E15: =C15^2 -> 5.4947134e-06 | F15: =E15 -> 5.4947134e-06 | G15: =SQRT(F15) -> 0.0023440805 | I15: =C15-$I$4 -> 0.0022682588 | J15: =I15^2 -> 5.1449978e-06 | K15: =J14 -> 0.0001343782 | L15: =$J$4+$K$4*K15+$L$4*L14 -> 2.4875313e-05 | M15: =LN(1/SQRT(2*PI()*L15*EXP(-J15/(2*L15)))) -> 4.4335867 | N15: =SQRT(J15) -> 0.0022682588 | O15: =SQRT(L15) -> 0.0049875157
B16: 44526 | C16: -0.015853313 | E16: =C16^2 -> 0.00025132753 | F16: =E16 -> 0.00025132753 | G16: =SQRT(F16) -> 0.015853313 | I16: =C16-$I$4 -> -0.015929135 | J16: =I16^2 -> 0.00025373733 | K16: =J15 -> 5.1449978e-06 | L16: =$J$4+$K$4*K16+$L$4*L15 -> 2.4449604e-05 | M16: =LN(1/SQRT(2*PI()*L16*EXP(-J16/(2*L16)))) -> 6.985003 | N16: =SQRT(J16) -> 0.015929135 | O16: =SQRT(L16) -> 0.0049446541
B17: 44529 | C17: 0.0017649119 | E17: =C17^2 -> 3.114914e-06 | F17: =E17 -> 3.114914e-06 | G17: =SQRT(F17) -> 0.0017649119 | I17: =C17-$I$4 -> 0.0016890901 | J17: =I17^2 -> 2.8530255e-06 | K17: =J16 -> 0.00025373733 | L17: =$J$4+$K$4*K17+$L$4*L16 -> 4.409618e-05 | M17: =LN(1/SQRT(2*PI()*L17*EXP(-J17/(2*L17)))) -> 4.1118052 | N17: =SQRT(J17) -> 0.0016890901 | O17: =SQRT(L17) -> 0.0066404954
B18: 44530 | C18: -0.0049953223 | E18: =C18^2 -> 2.4953245e-05 | F18: =E18 -> 2.4953245e-05 | G18: =SQRT(F18) -> 0.0049953223 | I18: =C18-$I$4 -> -0.0050711441 | J18: =I18^2 -> 2.5716502e-05 | K18: =J17 -> 2.8530255e-06 | L18: =$J$4+$K$4*K18+$L$4*L17 -> 4.1658761e-05 | M18: =LN(1/SQRT(2*PI()*L18*EXP(-J18/(2*L18)))) -> 4.2783892 | N18: =SQRT(J18) -> 0.0050711441 | O18: =SQRT(L18) -> 0.0064543598
B19: 44531 | C19: 0.0087803176 | E19: =C19^2 -> 7.7093978e-05 | F19: =E19 -> 7.7093978e-05 | G19: =SQRT(F19) -> 0.0087803176 | I19: =C19-$I$4 -> 0.0087044959 | J19: =I19^2 -> 7.5768249e-05 | K19: =J18 -> 2.5716502e-05 | L19: =$J$4+$K$4*K19+$L$4*L18 -> 4.1295391e-05 | M19: =LN(1/SQRT(2*PI()*L19*EXP(-J19/(2*L19)))) -> 4.5871381 | N19: =SQRT(J19) -> 0.0087044959 | O19: =SQRT(L19) -> 0.006426149
... B25: 44539 | C25: 0.00080941374 | E25: =C25^2 -> 6.551506e-07 | F25: =E25 -> 6.551506e-07 | G25: =SQRT(F25) -> 0.00080941374 | I25: =C25-$I$4 -> 0.00073359199 | J25: =I25^2 -> 5.381572e-07 | K25: =J24 -> 4.3850025e-05 | L25: =$J$4+$K$4*K25+$L$4*L24 -> 6.6596416e-05 | M25: =LN(1/SQRT(2*PI()*L25*EXP(-J25/(2*L25)))) -> 3.8915116 | N25: =SQRT(J25) -> 0.00073359199 | O25: =SQRT(L25) -> 0.0081606627
B26: 44540 | C26: 7.965852e-06 | E26: =C26^2 -> 6.3454799e-11 | F26: =E26 -> 6.3454799e-11 | G26: =SQRT(F26) -> 7.965852e-06 | I26: =C26-$I$4 -> -6.7855903e-05 | J26: =I26^2 -> 4.6044236e-09 | K26: =J25 -> 5.381572e-07 | L26: =$J$4+$K$4*K26+$L$4*L25 -> 6.1833726e-05 | M26: =LN(1/SQRT(2*PI()*L26*EXP(-J26/(2*L26)))) -> 3.9266109 | N26: =SQRT(J26) -> 6.7855903e-05 | O26: =SQRT(L26) -> 0.0078634424 | Q26: Comments
B27: 44543 | C27: -0.0044769852 | E27: =C27^2 -> 2.0043396e-05 | F27: =E27 -> 2.0043396e-05 | G27: =SQRT(F27) -> 0.0044769852 | I27: =C27-$I$4 -> -0.0045528069 | J27: =I27^2 -> 2.0728051e-05 | K27: =J26 -> 4.6044236e-09 | L27: =$J$4+$K$4*K27+$L$4*L26 -> 5.7480754e-05 | M27: =LN(1/SQRT(2*PI()*L27*EXP(-J27/(2*L27)))) -> 4.0532438 | N27: =SQRT(J27) -> 0.0045528069 | O27: =SQRT(L27) -> 0.0075816063 | Q27: The EWMA model captures spikes in volatility fairly quickly due to its exponential weighting (more weight to recent observations).
B28: 44544 | C28: -0.011130915 | E28: =C28^2 -> 0.00012389726 | F28: =E28 -> 0.00012389726 | G28: =SQRT(F28) -> 0.011130915 | I28: =C28-$I$4 -> -0.011206737 | J28: =I28^2 -> 0.00012559094 | K28: =J27 -> 2.0728051e-05 | L28: =$J$4+$K$4*K28+$L$4*L27 -> 5.5211465e-05 | M28: =LN(1/SQRT(2*PI()*L28*EXP(-J28/(2*L28)))) -> 4.5519129 | N28: =SQRT(J28) -> 0.011206737 | O28: =SQRT(L28) -> 0.0074304418 | Q28: Grach model gives a better rapresentation of the volatility (EWMA tends to overestimate volatility )
B29: 44545 | C29: 0.0096181816 | E29: =C29^2 -> 9.2509417e-05 | F29: =E29 -> 9.2509417e-05 | G29: =SQRT(F29) -> 0.0096181816 | I29: =C29-$I$4 -> 0.0095423598 | J29: =I29^2 -> 9.1056631e-05 | K29: =J28 -> 0.00012559094 | L29: =$J$4+$K$4*K29+$L$4*L28 -> 6.1607839e-05 | M29: =LN(1/SQRT(2*PI()*L29*EXP(-J29/(2*L29)))) -> 4.2979232 | N29: =SQRT(J29) -> 0.0095423598 | O29: =SQRT(L29) -> 0.0078490661
B30: 44546 | C30: 0.020743403 | E30: =C30^2 -> 0.00043028877 | F30: =E30 -> 0.00043028877 | G30: =SQRT(F30) -> 0.020743403 | I30: =C30-$I$4 -> 0.020667581 | J30: =I30^2 -> 0.00042714891 | K30: =J29 -> 9.1056631e-05 | L30: =$J$4+$K$4*K30+$L$4*L29 -> 6.4613402e-05 | M30: =LN(1/SQRT(2*PI()*L30*EXP(-J30/(2*L30)))) -> 5.557316 | N30: =SQRT(J30) -> 0.020667581 | O30: =SQRT(L30) -> 0.0080382462
B31: 44547 | C31: -0.0058951016 | E31: =C31^2 -> 3.4752222e-05 | F31: =E31 -> 3.4752222e-05 | G31: =SQRT(F31) -> 0.0058951016 | I31: =C31-$I$4 -> -0.0059709233 | J31: =I31^2 -> 3.5651925e-05 | K31: =J30 -> 0.00042714891 | L31: =$J$4+$K$4*K31+$L$4*L30 -> 9.4415926e-05 | M31: =LN(1/SQRT(2*PI()*L31*EXP(-J31/(2*L31)))) -> 3.8093631 | N31: =SQRT(J31) -> 0.0059709233 | O31: =SQRT(L31) -> 0.0097167858
B32: 44550 | C32: -0.009877537 | E32: =C32^2 -> 9.7565737e-05 | F32: =E32 -> 9.7565737e-05 | G32: =SQRT(F32) -> 0.009877537 | I32: =C32-$I$4 -> -0.0099533587 | J32: =I32^2 -> 9.906935e-05 | K32: =J31 -> 3.5651925e-05 | L32: =$J$4+$K$4*K32+$L$4*L31 -> 8.9838382e-05 | M32: =LN(1/SQRT(2*PI()*L32*EXP(-J32/(2*L32)))) -> 4.0154983 | N32: =SQRT(J32) -> 0.0099533587 | O32: =SQRT(L32) -> 0.0094783111
B33: 44551 | C33: 0.0073586096 | E33: =C33^2 -> 5.4149135e-05 | F33: =E33 -> 5.4149135e-05 | G33: =SQRT(F33) -> 0.0073586096 | I33: =C33-$I$4 -> 0.0072827879 | J33: =I33^2 -> 5.3038999e-05 | K33: =J32 -> 9.906935e-05 | L33: =$J$4+$K$4*K33+$L$4*L32 -> 9.0806192e-05 | M33: =LN(1/SQRT(2*PI()*L33*EXP(-J33/(2*L33)))) -> 3.8804755 | N33: =SQRT(J33) -> 0.0072827879 | O33: =SQRT(L33) -> 0.0095292283
B34: 44552 | C34: 0.0024731266 | E34: =C34^2 -> 6.1163551e-06 | F34: =E34 -> 6.1163551e-06 | G34: =SQRT(F34) -> 0.0024731266 | I34: =C34-$I$4 -> 0.0023973048 | J34: =I34^2 -> 5.7470704e-06 | K34: =J33 -> 5.3038999e-05 | L34: =$J$4+$K$4*K34+$L$4*L33 -> 8.7972836e-05 | M34: =LN(1/SQRT(2*PI()*L34*EXP(-J34/(2*L34)))) -> 3.7666347 | N34: =SQRT(J34) -> 0.0023973048 | O34: =SQRT(L34) -> 0.0093793835
B35: 44553 | C35: 0.0056176437 | E35: =C35^2 -> 3.155792e-05 | F35: =E35 -> 3.155792e-05 | G35: =SQRT(F35) -> 0.0056176437 | I35: =C35-$I$4 -> 0.0055418219 | J35: =I35^2 -> 3.071179e-05 | K35: =J34 -> 5.7470704e-06 | L35: =$J$4+$K$4*K35+$L$4*L34 -> 8.159797e-05 | M35: =LN(1/SQRT(2*PI()*L35*EXP(-J35/(2*L35)))) -> 3.8820094 | N35: =SQRT(J35) -> 0.0055418219 | O35: =SQRT(L35) -> 0.0090331595
B36: 44557 | C36: 0.0063806907 | E36: =C36^2 -> 4.0713214e-05 | F36: =E36 -> 4.0713214e-05 | G36: =SQRT(F36) -> 0.0063806907 | I36: =C36-$I$4 -> 0.0063048689 | J36: =I36^2 -> 3.9751372e-05 | K36: =J35 -> 3.071179e-05 | L36: =$J$4+$K$4*K36+$L$4*L35 -> 7.7840744e-05 | M36: =LN(1/SQRT(2*PI()*L36*EXP(-J36/(2*L36)))) -> 3.9391532 | N36: =SQRT(J36) -> 0.0063048689 | O36: =SQRT(L36) -> 0.0088227401
B37: 44558 | C37: 0.0080540125 | E37: =C37^2 -> 6.4867118e-05 | F37: =E37 -> 6.4867118e-05 | G37: =SQRT(F37) -> 0.0080540125 | I37: =C37-$I$4 -> 0.0079781908 | J37: =I37^2 -> 6.3651528e-05 | K37: =J36 -> 3.9751372e-05 | L37: =$J$4+$K$4*K37+$L$4*L36 -> 7.5169075e-05 | M37: =LN(1/SQRT(2*PI()*L37*EXP(-J37/(2*L37)))) -> 4.0406413 | N37: =SQRT(J37) -> 0.0079781908 | O37: =SQRT(L37) -> 0.0086700101
B38: 44559 | C38: -0.0033898438 | E38: =C38^2 -> 1.1491041e-05 | F38: =E38 -> 1.1491041e-05 | G38: =SQRT(F38) -> 0.0033898438 | I38: =C38-$I$4 -> -0.0034656655 | J38: =I38^2 -> 1.2010838e-05 | K38: =J37 -> 6.3651528e-05 | L38: =$J$4+$K$4*K38+$L$4*L37 -> 7.4677258e-05 | M38: =LN(1/SQRT(2*PI()*L38*EXP(-J38/(2*L38)))) -> 3.8724381 | N38: =SQRT(J38) -> 0.0034656655 | O38: =SQRT(L38) -> 0.0086416004
B39: 44560 | C39: -0.0039379842 | E39: =C39^2 -> 1.550772e-05 | F39: =E39 -> 1.550772e-05 | G39: =SQRT(F39) -> 0.0039379842 | I39: =C39-$I$4 -> -0.004013806 | J39: =I39^2 -> 1.6110638e-05 | K39: =J38 -> 1.2010838e-05 | L39: =$J$4+$K$4*K39+$L$4*L38 -> 7.0070931e-05 | M39: =LN(1/SQRT(2*PI()*L39*EXP(-J39/(2*L39)))) -> 3.9215425 | N39: =SQRT(J39) -> 0.004013806 | O39: =SQRT(L39) -> 0.0083708381
